2025-01-06 12:43:15,508 ERROR scheduler Exception in Enqueue Events for Site keval
Traceback (most recent call last):
  File "/home/hp/Desktop/office_work/Office_work/frappe-bench/env/lib/python3.10/site-packages/pymysql/connections.py", line 782, in _read_bytes
    data = self._rfile.read(num_bytes)
  File "/usr/lib/python3.10/socket.py", line 705, in readinto
    return self._sock.recv_into(b)
ConnectionResetError: [Errno 104] Connection reset by peer

During handling of the above exception, another exception occurred:

Traceback (most recent call last):
  File "/home/hp/Desktop/office_work/Office_work/frappe-bench/apps/frappe/frappe/utils/scheduler.py", line 75, in enqueue_events_for_site
    if is_scheduler_inactive():
  File "/home/hp/Desktop/office_work/Office_work/frappe-bench/apps/frappe/frappe/utils/scheduler.py", line 117, in is_scheduler_inactive
    if is_scheduler_disabled(verbose=verbose):
  File "/home/hp/Desktop/office_work/Office_work/frappe-bench/apps/frappe/frappe/utils/scheduler.py", line 130, in is_scheduler_disabled
    frappe.db.get_single_value("System Settings", "enable_scheduler")
  File "/home/hp/Desktop/office_work/Office_work/frappe-bench/apps/frappe/frappe/database/database.py", line 834, in get_single_value
    ).run()
  File "/home/hp/Desktop/office_work/Office_work/frappe-bench/apps/frappe/frappe/query_builder/utils.py", line 87, in execute_query
    result = frappe.db.sql(query, params, *args, **kwargs)  # nosemgrep
  File "/home/hp/Desktop/office_work/Office_work/frappe-bench/apps/frappe/frappe/database/database.py", line 204, in sql
    self.connect()
  File "/home/hp/Desktop/office_work/Office_work/frappe-bench/apps/frappe/frappe/database/database.py", line 109, in connect
    self._conn: "MariadbConnection" | "PostgresConnection" = self.get_connection()
  File "/home/hp/Desktop/office_work/Office_work/frappe-bench/apps/frappe/frappe/database/mariadb/database.py", line 107, in get_connection
    conn = self._get_connection()
  File "/home/hp/Desktop/office_work/Office_work/frappe-bench/apps/frappe/frappe/database/mariadb/database.py", line 113, in _get_connection
    return self.create_connection()
  File "/home/hp/Desktop/office_work/Office_work/frappe-bench/apps/frappe/frappe/database/mariadb/database.py", line 116, in create_connection
    return pymysql.connect(**self.get_connection_settings())
  File "/home/hp/Desktop/office_work/Office_work/frappe-bench/env/lib/python3.10/site-packages/pymysql/connections.py", line 361, in __init__
    self.connect()
  File "/home/hp/Desktop/office_work/Office_work/frappe-bench/env/lib/python3.10/site-packages/pymysql/connections.py", line 668, in connect
    self._get_server_information()
  File "/home/hp/Desktop/office_work/Office_work/frappe-bench/env/lib/python3.10/site-packages/pymysql/connections.py", line 1098, in _get_server_information
    packet = self._read_packet()
  File "/home/hp/Desktop/office_work/Office_work/frappe-bench/env/lib/python3.10/site-packages/pymysql/connections.py", line 744, in _read_packet
    packet_header = self._read_bytes(4)
  File "/home/hp/Desktop/office_work/Office_work/frappe-bench/env/lib/python3.10/site-packages/pymysql/connections.py", line 788, in _read_bytes
    raise err.OperationalError(
pymysql.err.OperationalError: (2013, 'Lost connection to MySQL server during query ([Errno 104] Connection reset by peer)')
